[2023-07-02 20:18:34,042][classifier.train][INFO] - Instantiating datamodule <classifier.data.image_folder_datamodule.ImageFolderDataModule>
[2023-07-02 20:18:34,045][classifier.utils.utils][ERROR] - 
Traceback (most recent call last):
  File "/workspace/.pyenv_mirror/user/current/lib/python3.11/site-packages/hydra/_internal/utils.py", line 644, in _locate
    obj = getattr(obj, part)
          ^^^^^^^^^^^^^^^^^^
AttributeError: module 'classifier' has no attribute 'data'

During handling of the above exception, another exception occurred:

Traceback (most recent call last):
  File "/workspace/.pyenv_mirror/user/current/lib/python3.11/site-packages/hydra/_internal/utils.py", line 650, in _locate
    obj = import_module(mod)
          ^^^^^^^^^^^^^^^^^^
  File "/home/gitpod/.pyenv/versions/3.11.1/lib/python3.11/importlib/__init__.py", line 126, in import_module
    return _bootstrap._gcd_import(name[level:], package, level)
           ^^^^^^^^^^^^^^^^^^^^^^^^^^^^^^^^^^^^^^^^^^^^^^^^^^^^
  File "<frozen importlib._bootstrap>", line 1206, in _gcd_import
  File "<frozen importlib._bootstrap>", line 1178, in _find_and_load
  File "<frozen importlib._bootstrap>", line 1142, in _find_and_load_unlocked
ModuleNotFoundError: No module named 'classifier.data'

The above exception was the direct cause of the following exception:

Traceback (most recent call last):
  File "/workspace/.pyenv_mirror/user/current/lib/python3.11/site-packages/hydra/_internal/instantiate/_instantiate2.py", line 134, in _resolve_target
    target = _locate(target)
             ^^^^^^^^^^^^^^^
  File "/workspace/.pyenv_mirror/user/current/lib/python3.11/site-packages/hydra/_internal/utils.py", line 653, in _locate
    raise ImportError(
ImportError: Error loading 'classifier.data.image_folder_datamodule.ImageFolderDataModule':
ModuleNotFoundError("No module named 'classifier.data'")
Are you sure that 'data' is importable from module 'classifier'?

The above exception was the direct cause of the following exception:

Traceback (most recent call last):
  File "/workspace/TSOA-Emlops-Deep-Learning-package/classifier/utils/utils.py", line 65, in wrap
    metric_dict, object_dict = task_func(cfg=cfg)
                               ^^^^^^^^^^^^^^^^^^
  File "/workspace/TSOA-Emlops-Deep-Learning-package/classifier/train.py", line 40, in train
    datamodule: LightningDataModule = hydra.utils.instantiate(cfg.data)
                                      ^^^^^^^^^^^^^^^^^^^^^^^^^^^^^^^^^
  File "/workspace/.pyenv_mirror/user/current/lib/python3.11/site-packages/hydra/_internal/instantiate/_instantiate2.py", line 226, in instantiate
    return instantiate_node(
           ^^^^^^^^^^^^^^^^^
  File "/workspace/.pyenv_mirror/user/current/lib/python3.11/site-packages/hydra/_internal/instantiate/_instantiate2.py", line 333, in instantiate_node
    _target_ = _resolve_target(node.get(_Keys.TARGET), full_key)
               ^^^^^^^^^^^^^^^^^^^^^^^^^^^^^^^^^^^^^^^^^^^^^^^^^
  File "/workspace/.pyenv_mirror/user/current/lib/python3.11/site-packages/hydra/_internal/instantiate/_instantiate2.py", line 139, in _resolve_target
    raise InstantiationException(msg) from e
hydra.errors.InstantiationException: Error locating target 'classifier.data.image_folder_datamodule.ImageFolderDataModule', set env var HYDRA_FULL_ERROR=1 to see chained exception.
full_key: data
[2023-07-02 20:18:34,049][classifier.utils.utils][INFO] - Output dir: /workspace/TSOA-Emlops-Deep-Learning-package/logs/train/runs/2023-07-02_20-18-33
[2023-07-02 20:19:05,040][classifier.train][INFO] - Instantiating datamodule <classifier.data.image_folder_datamodule.ImageFolderDataModule>
[2023-07-02 20:19:05,043][classifier.utils.utils][ERROR] - 
Traceback (most recent call last):
  File "/workspace/.pyenv_mirror/user/current/lib/python3.11/site-packages/hydra/_internal/utils.py", line 644, in _locate
    obj = getattr(obj, part)
          ^^^^^^^^^^^^^^^^^^
AttributeError: module 'classifier' has no attribute 'data'

During handling of the above exception, another exception occurred:

Traceback (most recent call last):
  File "/workspace/.pyenv_mirror/user/current/lib/python3.11/site-packages/hydra/_internal/utils.py", line 650, in _locate
    obj = import_module(mod)
          ^^^^^^^^^^^^^^^^^^
  File "/home/gitpod/.pyenv/versions/3.11.1/lib/python3.11/importlib/__init__.py", line 126, in import_module
    return _bootstrap._gcd_import(name[level:], package, level)
           ^^^^^^^^^^^^^^^^^^^^^^^^^^^^^^^^^^^^^^^^^^^^^^^^^^^^
  File "<frozen importlib._bootstrap>", line 1206, in _gcd_import
  File "<frozen importlib._bootstrap>", line 1178, in _find_and_load
  File "<frozen importlib._bootstrap>", line 1142, in _find_and_load_unlocked
ModuleNotFoundError: No module named 'classifier.data'

The above exception was the direct cause of the following exception:

Traceback (most recent call last):
  File "/workspace/.pyenv_mirror/user/current/lib/python3.11/site-packages/hydra/_internal/instantiate/_instantiate2.py", line 134, in _resolve_target
    target = _locate(target)
             ^^^^^^^^^^^^^^^
  File "/workspace/.pyenv_mirror/user/current/lib/python3.11/site-packages/hydra/_internal/utils.py", line 653, in _locate
    raise ImportError(
ImportError: Error loading 'classifier.data.image_folder_datamodule.ImageFolderDataModule':
ModuleNotFoundError("No module named 'classifier.data'")
Are you sure that 'data' is importable from module 'classifier'?

The above exception was the direct cause of the following exception:

Traceback (most recent call last):
  File "/workspace/TSOA-Emlops-Deep-Learning-package/classifier/utils/utils.py", line 65, in wrap
    metric_dict, object_dict = task_func(cfg=cfg)
                               ^^^^^^^^^^^^^^^^^^
  File "/workspace/TSOA-Emlops-Deep-Learning-package/classifier/train.py", line 40, in train
    datamodule: LightningDataModule = hydra.utils.instantiate(cfg.data)
                                      ^^^^^^^^^^^^^^^^^^^^^^^^^^^^^^^^^
  File "/workspace/.pyenv_mirror/user/current/lib/python3.11/site-packages/hydra/_internal/instantiate/_instantiate2.py", line 226, in instantiate
    return instantiate_node(
           ^^^^^^^^^^^^^^^^^
  File "/workspace/.pyenv_mirror/user/current/lib/python3.11/site-packages/hydra/_internal/instantiate/_instantiate2.py", line 333, in instantiate_node
    _target_ = _resolve_target(node.get(_Keys.TARGET), full_key)
               ^^^^^^^^^^^^^^^^^^^^^^^^^^^^^^^^^^^^^^^^^^^^^^^^^
  File "/workspace/.pyenv_mirror/user/current/lib/python3.11/site-packages/hydra/_internal/instantiate/_instantiate2.py", line 139, in _resolve_target
    raise InstantiationException(msg) from e
hydra.errors.InstantiationException: Error locating target 'classifier.data.image_folder_datamodule.ImageFolderDataModule', set env var HYDRA_FULL_ERROR=1 to see chained exception.
full_key: data
[2023-07-02 20:19:05,045][classifier.utils.utils][INFO] - Output dir: /workspace/TSOA-Emlops-Deep-Learning-package/logs/train/runs/2023-07-02_20-19-04
[2023-07-02 20:20:38,466][classifier.train][INFO] - Instantiating datamodule <classifier.data.image_folder_datamodule.ImageFolderDataModule>
[2023-07-02 20:20:38,470][classifier.utils.utils][ERROR] - 
Traceback (most recent call last):
  File "/workspace/.pyenv_mirror/user/current/lib/python3.11/site-packages/hydra/_internal/utils.py", line 644, in _locate
    obj = getattr(obj, part)
          ^^^^^^^^^^^^^^^^^^
AttributeError: module 'classifier.data' has no attribute 'image_folder_datamodule'

During handling of the above exception, another exception occurred:

Traceback (most recent call last):
  File "/workspace/.pyenv_mirror/user/current/lib/python3.11/site-packages/hydra/_internal/utils.py", line 650, in _locate
    obj = import_module(mod)
          ^^^^^^^^^^^^^^^^^^
  File "/home/gitpod/.pyenv/versions/3.11.1/lib/python3.11/importlib/__init__.py", line 126, in import_module
    return _bootstrap._gcd_import(name[level:], package, level)
           ^^^^^^^^^^^^^^^^^^^^^^^^^^^^^^^^^^^^^^^^^^^^^^^^^^^^
  File "<frozen importlib._bootstrap>", line 1206, in _gcd_import
  File "<frozen importlib._bootstrap>", line 1178, in _find_and_load
  File "<frozen importlib._bootstrap>", line 1149, in _find_and_load_unlocked
  File "<frozen importlib._bootstrap>", line 690, in _load_unlocked
  File "<frozen importlib._bootstrap_external>", line 936, in exec_module
  File "<frozen importlib._bootstrap_external>", line 1074, in get_code
  File "<frozen importlib._bootstrap_external>", line 1004, in source_to_code
  File "<frozen importlib._bootstrap>", line 241, in _call_with_frames_removed
  File "/workspace/TSOA-Emlops-Deep-Learning-package/classifier/data/image_folder_datamodule.py", line 69
    def predict_dataloader(self):
                                 ^
IndentationError: unindent does not match any outer indentation level

The above exception was the direct cause of the following exception:

Traceback (most recent call last):
  File "/workspace/.pyenv_mirror/user/current/lib/python3.11/site-packages/hydra/_internal/instantiate/_instantiate2.py", line 134, in _resolve_target
    target = _locate(target)
             ^^^^^^^^^^^^^^^
  File "/workspace/.pyenv_mirror/user/current/lib/python3.11/site-packages/hydra/_internal/utils.py", line 658, in _locate
    raise ImportError(
ImportError: Error loading 'classifier.data.image_folder_datamodule.ImageFolderDataModule':
IndentationError('unindent does not match any outer indentation level', ('/workspace/TSOA-Emlops-Deep-Learning-package/classifier/data/image_folder_datamodule.py', 69, 35, '     def predict_dataloader(self):\n', 69, -1))

The above exception was the direct cause of the following exception:

Traceback (most recent call last):
  File "/workspace/TSOA-Emlops-Deep-Learning-package/classifier/utils/utils.py", line 65, in wrap
    metric_dict, object_dict = task_func(cfg=cfg)
                               ^^^^^^^^^^^^^^^^^^
  File "/workspace/TSOA-Emlops-Deep-Learning-package/classifier/train.py", line 40, in train
    datamodule: LightningDataModule = hydra.utils.instantiate(cfg.data)
                                      ^^^^^^^^^^^^^^^^^^^^^^^^^^^^^^^^^
  File "/workspace/.pyenv_mirror/user/current/lib/python3.11/site-packages/hydra/_internal/instantiate/_instantiate2.py", line 226, in instantiate
    return instantiate_node(
           ^^^^^^^^^^^^^^^^^
  File "/workspace/.pyenv_mirror/user/current/lib/python3.11/site-packages/hydra/_internal/instantiate/_instantiate2.py", line 333, in instantiate_node
    _target_ = _resolve_target(node.get(_Keys.TARGET), full_key)
               ^^^^^^^^^^^^^^^^^^^^^^^^^^^^^^^^^^^^^^^^^^^^^^^^^
  File "/workspace/.pyenv_mirror/user/current/lib/python3.11/site-packages/hydra/_internal/instantiate/_instantiate2.py", line 139, in _resolve_target
    raise InstantiationException(msg) from e
hydra.errors.InstantiationException: Error locating target 'classifier.data.image_folder_datamodule.ImageFolderDataModule', set env var HYDRA_FULL_ERROR=1 to see chained exception.
full_key: data
[2023-07-02 20:20:38,472][classifier.utils.utils][INFO] - Output dir: /workspace/TSOA-Emlops-Deep-Learning-package/logs/train/runs/2023-07-02_20-20-38
