[2023-07-02 20:18:34,042][classifier.train][INFO] - Instantiating datamodule <classifier.data.image_folder_datamodule.ImageFolderDataModule>
[2023-07-02 20:18:34,045][classifier.utils.utils][ERROR] - 
Traceback (most recent call last):
  File "/workspace/.pyenv_mirror/user/current/lib/python3.11/site-packages/hydra/_internal/utils.py", line 644, in _locate
    obj = getattr(obj, part)
          ^^^^^^^^^^^^^^^^^^
AttributeError: module 'classifier' has no attribute 'data'

During handling of the above exception, another exception occurred:

Traceback (most recent call last):
  File "/workspace/.pyenv_mirror/user/current/lib/python3.11/site-packages/hydra/_internal/utils.py", line 650, in _locate
    obj = import_module(mod)
          ^^^^^^^^^^^^^^^^^^
  File "/home/gitpod/.pyenv/versions/3.11.1/lib/python3.11/importlib/__init__.py", line 126, in import_module
    return _bootstrap._gcd_import(name[level:], package, level)
           ^^^^^^^^^^^^^^^^^^^^^^^^^^^^^^^^^^^^^^^^^^^^^^^^^^^^
  File "<frozen importlib._bootstrap>", line 1206, in _gcd_import
  File "<frozen importlib._bootstrap>", line 1178, in _find_and_load
  File "<frozen importlib._bootstrap>", line 1142, in _find_and_load_unlocked
ModuleNotFoundError: No module named 'classifier.data'

The above exception was the direct cause of the following exception:

Traceback (most recent call last):
  File "/workspace/.pyenv_mirror/user/current/lib/python3.11/site-packages/hydra/_internal/instantiate/_instantiate2.py", line 134, in _resolve_target
    target = _locate(target)
             ^^^^^^^^^^^^^^^
  File "/workspace/.pyenv_mirror/user/current/lib/python3.11/site-packages/hydra/_internal/utils.py", line 653, in _locate
    raise ImportError(
ImportError: Error loading 'classifier.data.image_folder_datamodule.ImageFolderDataModule':
ModuleNotFoundError("No module named 'classifier.data'")
Are you sure that 'data' is importable from module 'classifier'?

The above exception was the direct cause of the following exception:

Traceback (most recent call last):
  File "/workspace/TSOA-Emlops-Deep-Learning-package/classifier/utils/utils.py", line 65, in wrap
    metric_dict, object_dict = task_func(cfg=cfg)
                               ^^^^^^^^^^^^^^^^^^
  File "/workspace/TSOA-Emlops-Deep-Learning-package/classifier/train.py", line 40, in train
    datamodule: LightningDataModule = hydra.utils.instantiate(cfg.data)
                                      ^^^^^^^^^^^^^^^^^^^^^^^^^^^^^^^^^
  File "/workspace/.pyenv_mirror/user/current/lib/python3.11/site-packages/hydra/_internal/instantiate/_instantiate2.py", line 226, in instantiate
    return instantiate_node(
           ^^^^^^^^^^^^^^^^^
  File "/workspace/.pyenv_mirror/user/current/lib/python3.11/site-packages/hydra/_internal/instantiate/_instantiate2.py", line 333, in instantiate_node
    _target_ = _resolve_target(node.get(_Keys.TARGET), full_key)
               ^^^^^^^^^^^^^^^^^^^^^^^^^^^^^^^^^^^^^^^^^^^^^^^^^
  File "/workspace/.pyenv_mirror/user/current/lib/python3.11/site-packages/hydra/_internal/instantiate/_instantiate2.py", line 139, in _resolve_target
    raise InstantiationException(msg) from e
hydra.errors.InstantiationException: Error locating target 'classifier.data.image_folder_datamodule.ImageFolderDataModule', set env var HYDRA_FULL_ERROR=1 to see chained exception.
full_key: data
[2023-07-02 20:18:34,049][classifier.utils.utils][INFO] - Output dir: /workspace/TSOA-Emlops-Deep-Learning-package/logs/train/runs/2023-07-02_20-18-33
[2023-07-02 20:19:05,040][classifier.train][INFO] - Instantiating datamodule <classifier.data.image_folder_datamodule.ImageFolderDataModule>
[2023-07-02 20:19:05,043][classifier.utils.utils][ERROR] - 
Traceback (most recent call last):
  File "/workspace/.pyenv_mirror/user/current/lib/python3.11/site-packages/hydra/_internal/utils.py", line 644, in _locate
    obj = getattr(obj, part)
          ^^^^^^^^^^^^^^^^^^
AttributeError: module 'classifier' has no attribute 'data'

During handling of the above exception, another exception occurred:

Traceback (most recent call last):
  File "/workspace/.pyenv_mirror/user/current/lib/python3.11/site-packages/hydra/_internal/utils.py", line 650, in _locate
    obj = import_module(mod)
          ^^^^^^^^^^^^^^^^^^
  File "/home/gitpod/.pyenv/versions/3.11.1/lib/python3.11/importlib/__init__.py", line 126, in import_module
    return _bootstrap._gcd_import(name[level:], package, level)
           ^^^^^^^^^^^^^^^^^^^^^^^^^^^^^^^^^^^^^^^^^^^^^^^^^^^^
  File "<frozen importlib._bootstrap>", line 1206, in _gcd_import
  File "<frozen importlib._bootstrap>", line 1178, in _find_and_load
  File "<frozen importlib._bootstrap>", line 1142, in _find_and_load_unlocked
ModuleNotFoundError: No module named 'classifier.data'

The above exception was the direct cause of the following exception:

Traceback (most recent call last):
  File "/workspace/.pyenv_mirror/user/current/lib/python3.11/site-packages/hydra/_internal/instantiate/_instantiate2.py", line 134, in _resolve_target
    target = _locate(target)
             ^^^^^^^^^^^^^^^
  File "/workspace/.pyenv_mirror/user/current/lib/python3.11/site-packages/hydra/_internal/utils.py", line 653, in _locate
    raise ImportError(
ImportError: Error loading 'classifier.data.image_folder_datamodule.ImageFolderDataModule':
ModuleNotFoundError("No module named 'classifier.data'")
Are you sure that 'data' is importable from module 'classifier'?

The above exception was the direct cause of the following exception:

Traceback (most recent call last):
  File "/workspace/TSOA-Emlops-Deep-Learning-package/classifier/utils/utils.py", line 65, in wrap
    metric_dict, object_dict = task_func(cfg=cfg)
                               ^^^^^^^^^^^^^^^^^^
  File "/workspace/TSOA-Emlops-Deep-Learning-package/classifier/train.py", line 40, in train
    datamodule: LightningDataModule = hydra.utils.instantiate(cfg.data)
                                      ^^^^^^^^^^^^^^^^^^^^^^^^^^^^^^^^^
  File "/workspace/.pyenv_mirror/user/current/lib/python3.11/site-packages/hydra/_internal/instantiate/_instantiate2.py", line 226, in instantiate
    return instantiate_node(
           ^^^^^^^^^^^^^^^^^
  File "/workspace/.pyenv_mirror/user/current/lib/python3.11/site-packages/hydra/_internal/instantiate/_instantiate2.py", line 333, in instantiate_node
    _target_ = _resolve_target(node.get(_Keys.TARGET), full_key)
               ^^^^^^^^^^^^^^^^^^^^^^^^^^^^^^^^^^^^^^^^^^^^^^^^^
  File "/workspace/.pyenv_mirror/user/current/lib/python3.11/site-packages/hydra/_internal/instantiate/_instantiate2.py", line 139, in _resolve_target
    raise InstantiationException(msg) from e
hydra.errors.InstantiationException: Error locating target 'classifier.data.image_folder_datamodule.ImageFolderDataModule', set env var HYDRA_FULL_ERROR=1 to see chained exception.
full_key: data
[2023-07-02 20:19:05,045][classifier.utils.utils][INFO] - Output dir: /workspace/TSOA-Emlops-Deep-Learning-package/logs/train/runs/2023-07-02_20-19-04
[2023-07-02 20:20:38,466][classifier.train][INFO] - Instantiating datamodule <classifier.data.image_folder_datamodule.ImageFolderDataModule>
[2023-07-02 20:20:38,470][classifier.utils.utils][ERROR] - 
Traceback (most recent call last):
  File "/workspace/.pyenv_mirror/user/current/lib/python3.11/site-packages/hydra/_internal/utils.py", line 644, in _locate
    obj = getattr(obj, part)
          ^^^^^^^^^^^^^^^^^^
AttributeError: module 'classifier.data' has no attribute 'image_folder_datamodule'

During handling of the above exception, another exception occurred:

Traceback (most recent call last):
  File "/workspace/.pyenv_mirror/user/current/lib/python3.11/site-packages/hydra/_internal/utils.py", line 650, in _locate
    obj = import_module(mod)
          ^^^^^^^^^^^^^^^^^^
  File "/home/gitpod/.pyenv/versions/3.11.1/lib/python3.11/importlib/__init__.py", line 126, in import_module
    return _bootstrap._gcd_import(name[level:], package, level)
           ^^^^^^^^^^^^^^^^^^^^^^^^^^^^^^^^^^^^^^^^^^^^^^^^^^^^
  File "<frozen importlib._bootstrap>", line 1206, in _gcd_import
  File "<frozen importlib._bootstrap>", line 1178, in _find_and_load
  File "<frozen importlib._bootstrap>", line 1149, in _find_and_load_unlocked
  File "<frozen importlib._bootstrap>", line 690, in _load_unlocked
  File "<frozen importlib._bootstrap_external>", line 936, in exec_module
  File "<frozen importlib._bootstrap_external>", line 1074, in get_code
  File "<frozen importlib._bootstrap_external>", line 1004, in source_to_code
  File "<frozen importlib._bootstrap>", line 241, in _call_with_frames_removed
  File "/workspace/TSOA-Emlops-Deep-Learning-package/classifier/data/image_folder_datamodule.py", line 69
    def predict_dataloader(self):
                                 ^
IndentationError: unindent does not match any outer indentation level

The above exception was the direct cause of the following exception:

Traceback (most recent call last):
  File "/workspace/.pyenv_mirror/user/current/lib/python3.11/site-packages/hydra/_internal/instantiate/_instantiate2.py", line 134, in _resolve_target
    target = _locate(target)
             ^^^^^^^^^^^^^^^
  File "/workspace/.pyenv_mirror/user/current/lib/python3.11/site-packages/hydra/_internal/utils.py", line 658, in _locate
    raise ImportError(
ImportError: Error loading 'classifier.data.image_folder_datamodule.ImageFolderDataModule':
IndentationError('unindent does not match any outer indentation level', ('/workspace/TSOA-Emlops-Deep-Learning-package/classifier/data/image_folder_datamodule.py', 69, 35, '     def predict_dataloader(self):\n', 69, -1))

The above exception was the direct cause of the following exception:

Traceback (most recent call last):
  File "/workspace/TSOA-Emlops-Deep-Learning-package/classifier/utils/utils.py", line 65, in wrap
    metric_dict, object_dict = task_func(cfg=cfg)
                               ^^^^^^^^^^^^^^^^^^
  File "/workspace/TSOA-Emlops-Deep-Learning-package/classifier/train.py", line 40, in train
    datamodule: LightningDataModule = hydra.utils.instantiate(cfg.data)
                                      ^^^^^^^^^^^^^^^^^^^^^^^^^^^^^^^^^
  File "/workspace/.pyenv_mirror/user/current/lib/python3.11/site-packages/hydra/_internal/instantiate/_instantiate2.py", line 226, in instantiate
    return instantiate_node(
           ^^^^^^^^^^^^^^^^^
  File "/workspace/.pyenv_mirror/user/current/lib/python3.11/site-packages/hydra/_internal/instantiate/_instantiate2.py", line 333, in instantiate_node
    _target_ = _resolve_target(node.get(_Keys.TARGET), full_key)
               ^^^^^^^^^^^^^^^^^^^^^^^^^^^^^^^^^^^^^^^^^^^^^^^^^
  File "/workspace/.pyenv_mirror/user/current/lib/python3.11/site-packages/hydra/_internal/instantiate/_instantiate2.py", line 139, in _resolve_target
    raise InstantiationException(msg) from e
hydra.errors.InstantiationException: Error locating target 'classifier.data.image_folder_datamodule.ImageFolderDataModule', set env var HYDRA_FULL_ERROR=1 to see chained exception.
full_key: data
[2023-07-02 20:20:38,472][classifier.utils.utils][INFO] - Output dir: /workspace/TSOA-Emlops-Deep-Learning-package/logs/train/runs/2023-07-02_20-20-38
[2023-07-02 20:39:51,224][classifier.train][INFO] - Instantiating datamodule <classifier.data.image_folder_datamodule.ImageFolderDataModule>
[2023-07-02 20:39:51,230][classifier.utils.utils][ERROR] - 
Traceback (most recent call last):
  File "/workspace/.pyenv_mirror/user/current/lib/python3.11/site-packages/hydra/_internal/utils.py", line 644, in _locate
    obj = getattr(obj, part)
          ^^^^^^^^^^^^^^^^^^
AttributeError: module 'classifier.data' has no attribute 'image_folder_datamodule'

During handling of the above exception, another exception occurred:

Traceback (most recent call last):
  File "/workspace/.pyenv_mirror/user/current/lib/python3.11/site-packages/hydra/_internal/utils.py", line 650, in _locate
    obj = import_module(mod)
          ^^^^^^^^^^^^^^^^^^
  File "/home/gitpod/.pyenv/versions/3.11.1/lib/python3.11/importlib/__init__.py", line 126, in import_module
    return _bootstrap._gcd_import(name[level:], package, level)
           ^^^^^^^^^^^^^^^^^^^^^^^^^^^^^^^^^^^^^^^^^^^^^^^^^^^^
  File "<frozen importlib._bootstrap>", line 1206, in _gcd_import
  File "<frozen importlib._bootstrap>", line 1178, in _find_and_load
  File "<frozen importlib._bootstrap>", line 1149, in _find_and_load_unlocked
  File "<frozen importlib._bootstrap>", line 690, in _load_unlocked
  File "<frozen importlib._bootstrap_external>", line 936, in exec_module
  File "<frozen importlib._bootstrap_external>", line 1074, in get_code
  File "<frozen importlib._bootstrap_external>", line 1004, in source_to_code
  File "<frozen importlib._bootstrap>", line 241, in _call_with_frames_removed
  File "/workspace/TSOA-Emlops-Deep-Learning-package/classifier/data/image_folder_datamodule.py", line 69
    def predict_dataloader(self):
                                 ^
IndentationError: unindent does not match any outer indentation level

The above exception was the direct cause of the following exception:

Traceback (most recent call last):
  File "/workspace/.pyenv_mirror/user/current/lib/python3.11/site-packages/hydra/_internal/instantiate/_instantiate2.py", line 134, in _resolve_target
    target = _locate(target)
             ^^^^^^^^^^^^^^^
  File "/workspace/.pyenv_mirror/user/current/lib/python3.11/site-packages/hydra/_internal/utils.py", line 658, in _locate
    raise ImportError(
ImportError: Error loading 'classifier.data.image_folder_datamodule.ImageFolderDataModule':
IndentationError('unindent does not match any outer indentation level', ('/workspace/TSOA-Emlops-Deep-Learning-package/classifier/data/image_folder_datamodule.py', 69, 35, '     def predict_dataloader(self):\n', 69, -1))

The above exception was the direct cause of the following exception:

Traceback (most recent call last):
  File "/workspace/TSOA-Emlops-Deep-Learning-package/classifier/utils/utils.py", line 65, in wrap
    metric_dict, object_dict = task_func(cfg=cfg)
                               ^^^^^^^^^^^^^^^^^^
  File "/workspace/TSOA-Emlops-Deep-Learning-package/classifier/train.py", line 40, in train
    datamodule: LightningDataModule = hydra.utils.instantiate(cfg.data)
                                      ^^^^^^^^^^^^^^^^^^^^^^^^^^^^^^^^^
  File "/workspace/.pyenv_mirror/user/current/lib/python3.11/site-packages/hydra/_internal/instantiate/_instantiate2.py", line 226, in instantiate
    return instantiate_node(
           ^^^^^^^^^^^^^^^^^
  File "/workspace/.pyenv_mirror/user/current/lib/python3.11/site-packages/hydra/_internal/instantiate/_instantiate2.py", line 333, in instantiate_node
    _target_ = _resolve_target(node.get(_Keys.TARGET), full_key)
               ^^^^^^^^^^^^^^^^^^^^^^^^^^^^^^^^^^^^^^^^^^^^^^^^^
  File "/workspace/.pyenv_mirror/user/current/lib/python3.11/site-packages/hydra/_internal/instantiate/_instantiate2.py", line 139, in _resolve_target
    raise InstantiationException(msg) from e
hydra.errors.InstantiationException: Error locating target 'classifier.data.image_folder_datamodule.ImageFolderDataModule', set env var HYDRA_FULL_ERROR=1 to see chained exception.
full_key: data
[2023-07-02 20:39:51,235][classifier.utils.utils][INFO] - Output dir: /workspace/TSOA-Emlops-Deep-Learning-package/logs/train/runs/2023-07-02_20-39-51
[2023-07-02 20:41:16,158][classifier.train][INFO] - Instantiating datamodule <classifier.data.image_folder_datamodule.ImageFolderDataModule>
[2023-07-02 20:41:16,159][classifier.utils.utils][ERROR] - 
Traceback (most recent call last):
  File "/workspace/TSOA-Emlops-Deep-Learning-package/classifier/utils/utils.py", line 65, in wrap
    metric_dict, object_dict = task_func(cfg=cfg)
                               ^^^^^^^^^^^^^^^^^^
  File "/workspace/TSOA-Emlops-Deep-Learning-package/classifier/train.py", line 40, in train
    datamodule: LightningDataModule = hydra.utils.instantiate(cfg.datamodule)
                                                              ^^^^^^^^^^^^^^
  File "/workspace/.pyenv_mirror/user/current/lib/python3.11/site-packages/omegaconf/dictconfig.py", line 359, in __getattr__
    self._format_and_raise(key=key, value=None, cause=e)
  File "/workspace/.pyenv_mirror/user/current/lib/python3.11/site-packages/omegaconf/base.py", line 231, in _format_and_raise
    format_and_raise(
  File "/workspace/.pyenv_mirror/user/current/lib/python3.11/site-packages/omegaconf/_utils.py", line 819, in format_and_raise
    _raise(ex, cause)
  File "/workspace/.pyenv_mirror/user/current/lib/python3.11/site-packages/omegaconf/_utils.py", line 797, in _raise
    raise ex.with_traceback(sys.exc_info()[2])  # set env var OC_CAUSE=1 for full trace
    ^^^^^^^^^^^^^^^^^^^^^^^^^^^^^^^^^^^^^^^^^^
  File "/workspace/.pyenv_mirror/user/current/lib/python3.11/site-packages/omegaconf/dictconfig.py", line 351, in __getattr__
    return self._get_impl(
           ^^^^^^^^^^^^^^^
  File "/workspace/.pyenv_mirror/user/current/lib/python3.11/site-packages/omegaconf/dictconfig.py", line 442, in _get_impl
    node = self._get_child(
           ^^^^^^^^^^^^^^^^
  File "/workspace/.pyenv_mirror/user/current/lib/python3.11/site-packages/omegaconf/basecontainer.py", line 73, in _get_child
    child = self._get_node(
            ^^^^^^^^^^^^^^^
  File "/workspace/.pyenv_mirror/user/current/lib/python3.11/site-packages/omegaconf/dictconfig.py", line 475, in _get_node
    self._validate_get(key)
  File "/workspace/.pyenv_mirror/user/current/lib/python3.11/site-packages/omegaconf/dictconfig.py", line 164, in _validate_get
    self._format_and_raise(
  File "/workspace/.pyenv_mirror/user/current/lib/python3.11/site-packages/omegaconf/base.py", line 231, in _format_and_raise
    format_and_raise(
  File "/workspace/.pyenv_mirror/user/current/lib/python3.11/site-packages/omegaconf/_utils.py", line 899, in format_and_raise
    _raise(ex, cause)
  File "/workspace/.pyenv_mirror/user/current/lib/python3.11/site-packages/omegaconf/_utils.py", line 797, in _raise
    raise ex.with_traceback(sys.exc_info()[2])  # set env var OC_CAUSE=1 for full trace
    ^^^^^^^^^^^^^^^^^^^^^^^^^^^^^^^^^^^^^^^^^^
omegaconf.errors.ConfigAttributeError: Key 'datamodule' is not in struct
    full_key: datamodule
    object_type=dict
[2023-07-02 20:41:16,168][classifier.utils.utils][INFO] - Output dir: /workspace/TSOA-Emlops-Deep-Learning-package/logs/train/runs/2023-07-02_20-41-16
[2023-07-02 20:43:13,189][classifier.train][INFO] - Instantiating datamodule <classifier.data.image_folder_datamodule.ImageFolderDataModule>
[2023-07-02 20:43:13,192][classifier.utils.utils][ERROR] - 
Traceback (most recent call last):
  File "/workspace/.pyenv_mirror/user/current/lib/python3.11/site-packages/hydra/_internal/utils.py", line 644, in _locate
    obj = getattr(obj, part)
          ^^^^^^^^^^^^^^^^^^
AttributeError: module 'classifier.data' has no attribute 'image_folder_datamodule'

During handling of the above exception, another exception occurred:

Traceback (most recent call last):
  File "/workspace/.pyenv_mirror/user/current/lib/python3.11/site-packages/hydra/_internal/utils.py", line 650, in _locate
    obj = import_module(mod)
          ^^^^^^^^^^^^^^^^^^
  File "/home/gitpod/.pyenv/versions/3.11.1/lib/python3.11/importlib/__init__.py", line 126, in import_module
    return _bootstrap._gcd_import(name[level:], package, level)
           ^^^^^^^^^^^^^^^^^^^^^^^^^^^^^^^^^^^^^^^^^^^^^^^^^^^^
  File "<frozen importlib._bootstrap>", line 1206, in _gcd_import
  File "<frozen importlib._bootstrap>", line 1178, in _find_and_load
  File "<frozen importlib._bootstrap>", line 1149, in _find_and_load_unlocked
  File "<frozen importlib._bootstrap>", line 690, in _load_unlocked
  File "<frozen importlib._bootstrap_external>", line 936, in exec_module
  File "<frozen importlib._bootstrap_external>", line 1074, in get_code
  File "<frozen importlib._bootstrap_external>", line 1004, in source_to_code
  File "<frozen importlib._bootstrap>", line 241, in _call_with_frames_removed
  File "/workspace/TSOA-Emlops-Deep-Learning-package/classifier/data/image_folder_datamodule.py", line 69
    def predict_dataloader(self):
                                 ^
IndentationError: unindent does not match any outer indentation level

The above exception was the direct cause of the following exception:

Traceback (most recent call last):
  File "/workspace/.pyenv_mirror/user/current/lib/python3.11/site-packages/hydra/_internal/instantiate/_instantiate2.py", line 134, in _resolve_target
    target = _locate(target)
             ^^^^^^^^^^^^^^^
  File "/workspace/.pyenv_mirror/user/current/lib/python3.11/site-packages/hydra/_internal/utils.py", line 658, in _locate
    raise ImportError(
ImportError: Error loading 'classifier.data.image_folder_datamodule.ImageFolderDataModule':
IndentationError('unindent does not match any outer indentation level', ('/workspace/TSOA-Emlops-Deep-Learning-package/classifier/data/image_folder_datamodule.py', 69, 35, '     def predict_dataloader(self):\n', 69, -1))

The above exception was the direct cause of the following exception:

Traceback (most recent call last):
  File "/workspace/TSOA-Emlops-Deep-Learning-package/classifier/utils/utils.py", line 65, in wrap
    metric_dict, object_dict = task_func(cfg=cfg)
                               ^^^^^^^^^^^^^^^^^^
  File "/workspace/TSOA-Emlops-Deep-Learning-package/classifier/train.py", line 40, in train
    datamodule: LightningDataModule = hydra.utils.instantiate(cfg.data)
                                      ^^^^^^^^^^^^^^^^^^^^^^^^^^^^^^^^^
  File "/workspace/.pyenv_mirror/user/current/lib/python3.11/site-packages/hydra/_internal/instantiate/_instantiate2.py", line 226, in instantiate
    return instantiate_node(
           ^^^^^^^^^^^^^^^^^
  File "/workspace/.pyenv_mirror/user/current/lib/python3.11/site-packages/hydra/_internal/instantiate/_instantiate2.py", line 333, in instantiate_node
    _target_ = _resolve_target(node.get(_Keys.TARGET), full_key)
               ^^^^^^^^^^^^^^^^^^^^^^^^^^^^^^^^^^^^^^^^^^^^^^^^^
  File "/workspace/.pyenv_mirror/user/current/lib/python3.11/site-packages/hydra/_internal/instantiate/_instantiate2.py", line 139, in _resolve_target
    raise InstantiationException(msg) from e
hydra.errors.InstantiationException: Error locating target 'classifier.data.image_folder_datamodule.ImageFolderDataModule', set env var HYDRA_FULL_ERROR=1 to see chained exception.
full_key: data
[2023-07-02 20:43:13,194][classifier.utils.utils][INFO] - Output dir: /workspace/TSOA-Emlops-Deep-Learning-package/logs/train/runs/2023-07-02_20-43-13
[2023-07-02 20:47:56,318][classifier.train][INFO] - Instantiating datamodule <classifier.data.image_folder_datamodule.ImageFolderDataModule>
[2023-07-02 20:47:56,322][classifier.utils.utils][ERROR] - 
Traceback (most recent call last):
  File "/workspace/.pyenv_mirror/user/current/lib/python3.11/site-packages/hydra/_internal/instantiate/_instantiate2.py", line 92, in _call_target
    return _target_(*args, **kwargs)
           ^^^^^^^^^^^^^^^^^^^^^^^^^
  File "/workspace/.pyenv_mirror/user/current/lib/python3.11/site-packages/torchvision/datasets/folder.py", line 309, in __init__
    super().__init__(
  File "/workspace/.pyenv_mirror/user/current/lib/python3.11/site-packages/torchvision/datasets/folder.py", line 144, in __init__
    classes, class_to_idx = self.find_classes(self.root)
                            ^^^^^^^^^^^^^^^^^^^^^^^^^^^^
  File "/workspace/.pyenv_mirror/user/current/lib/python3.11/site-packages/torchvision/datasets/folder.py", line 218, in find_classes
    return find_classes(directory)
           ^^^^^^^^^^^^^^^^^^^^^^^
  File "/workspace/.pyenv_mirror/user/current/lib/python3.11/site-packages/torchvision/datasets/folder.py", line 40, in find_classes
    classes = sorted(entry.name for entry in os.scandir(directory) if entry.is_dir())
                                             ^^^^^^^^^^^^^^^^^^^^^
FileNotFoundError: [Errno 2] No such file or directory: './data//PetImages_split/train'

The above exception was the direct cause of the following exception:

Traceback (most recent call last):
  File "/workspace/TSOA-Emlops-Deep-Learning-package/classifier/utils/utils.py", line 65, in wrap
    metric_dict, object_dict = task_func(cfg=cfg)
                               ^^^^^^^^^^^^^^^^^^
  File "/workspace/TSOA-Emlops-Deep-Learning-package/classifier/train.py", line 40, in train
    datamodule: LightningDataModule = hydra.utils.instantiate(cfg.data)
                                      ^^^^^^^^^^^^^^^^^^^^^^^^^^^^^^^^^
  File "/workspace/.pyenv_mirror/user/current/lib/python3.11/site-packages/hydra/_internal/instantiate/_instantiate2.py", line 226, in instantiate
    return instantiate_node(
           ^^^^^^^^^^^^^^^^^
  File "/workspace/.pyenv_mirror/user/current/lib/python3.11/site-packages/hydra/_internal/instantiate/_instantiate2.py", line 342, in instantiate_node
    value = instantiate_node(
            ^^^^^^^^^^^^^^^^^
  File "/workspace/.pyenv_mirror/user/current/lib/python3.11/site-packages/hydra/_internal/instantiate/_instantiate2.py", line 347, in instantiate_node
    return _call_target(_target_, partial, args, kwargs, full_key)
           ^^^^^^^^^^^^^^^^^^^^^^^^^^^^^^^^^^^^^^^^^^^^^^^^^^^^^^^
  File "/workspace/.pyenv_mirror/user/current/lib/python3.11/site-packages/hydra/_internal/instantiate/_instantiate2.py", line 97, in _call_target
    raise InstantiationException(msg) from e
hydra.errors.InstantiationException: Error in call to target 'torchvision.datasets.folder.ImageFolder':
FileNotFoundError(2, 'No such file or directory')
full_key: data.train_dataset
[2023-07-02 20:47:56,324][classifier.utils.utils][INFO] - Output dir: /workspace/TSOA-Emlops-Deep-Learning-package/logs/train/runs/2023-07-02_20-47-56
