[2023-07-21 19:16:55,601][classifier.train][INFO] - Instantiating datamodule <classifier.data.image_folder_datamodule.ImageFolderDataModule>
[2023-07-21 19:16:55,605][classifier.utils.utils][ERROR] - 
Traceback (most recent call last):
  File "/workspace/.pyenv_mirror/user/current/lib/python3.11/site-packages/hydra/_internal/instantiate/_instantiate2.py", line 92, in _call_target
    return _target_(*args, **kwargs)
           ^^^^^^^^^^^^^^^^^^^^^^^^^
  File "/workspace/.pyenv_mirror/user/current/lib/python3.11/site-packages/torchvision/datasets/folder.py", line 309, in __init__
    super().__init__(
  File "/workspace/.pyenv_mirror/user/current/lib/python3.11/site-packages/torchvision/datasets/folder.py", line 144, in __init__
    classes, class_to_idx = self.find_classes(self.root)
                            ^^^^^^^^^^^^^^^^^^^^^^^^^^^^
  File "/workspace/.pyenv_mirror/user/current/lib/python3.11/site-packages/torchvision/datasets/folder.py", line 218, in find_classes
    return find_classes(directory)
           ^^^^^^^^^^^^^^^^^^^^^^^
  File "/workspace/.pyenv_mirror/user/current/lib/python3.11/site-packages/torchvision/datasets/folder.py", line 40, in find_classes
    classes = sorted(entry.name for entry in os.scandir(directory) if entry.is_dir())
                                             ^^^^^^^^^^^^^^^^^^^^^
FileNotFoundError: [Errno 2] No such file or directory: './data//PetImages_split/train'

The above exception was the direct cause of the following exception:

Traceback (most recent call last):
  File "/workspace/TSOA-Emlops-Deep-Learning-package/classifier/utils/utils.py", line 65, in wrap
    metric_dict, object_dict = task_func(cfg=cfg)
                               ^^^^^^^^^^^^^^^^^^
  File "/workspace/TSOA-Emlops-Deep-Learning-package/classifier/train.py", line 40, in train
    datamodule: LightningDataModule = hydra.utils.instantiate(cfg.data)
                                      ^^^^^^^^^^^^^^^^^^^^^^^^^^^^^^^^^
  File "/workspace/.pyenv_mirror/user/current/lib/python3.11/site-packages/hydra/_internal/instantiate/_instantiate2.py", line 226, in instantiate
    return instantiate_node(
           ^^^^^^^^^^^^^^^^^
  File "/workspace/.pyenv_mirror/user/current/lib/python3.11/site-packages/hydra/_internal/instantiate/_instantiate2.py", line 342, in instantiate_node
    value = instantiate_node(
            ^^^^^^^^^^^^^^^^^
  File "/workspace/.pyenv_mirror/user/current/lib/python3.11/site-packages/hydra/_internal/instantiate/_instantiate2.py", line 347, in instantiate_node
    return _call_target(_target_, partial, args, kwargs, full_key)
           ^^^^^^^^^^^^^^^^^^^^^^^^^^^^^^^^^^^^^^^^^^^^^^^^^^^^^^^
  File "/workspace/.pyenv_mirror/user/current/lib/python3.11/site-packages/hydra/_internal/instantiate/_instantiate2.py", line 97, in _call_target
    raise InstantiationException(msg) from e
hydra.errors.InstantiationException: Error in call to target 'torchvision.datasets.folder.ImageFolder':
FileNotFoundError(2, 'No such file or directory')
full_key: data.train_dataset
[2023-07-21 19:16:55,607][classifier.utils.utils][INFO] - Output dir: /workspace/TSOA-Emlops-Deep-Learning-package/outputs/2023-07-21/19-16-55
