[2023-07-03 06:19:56,502][classifier.utils.utils][ERROR] - 
Traceback (most recent call last):
  File "/workspace/TSOA-Emlops-Deep-Learning-package/classifier/utils/utils.py", line 65, in wrap
    metric_dict, object_dict = task_func(cfg=cfg)
                               ^^^^^^^^^^^^^^^^^^
  File "/workspace/TSOA-Emlops-Deep-Learning-package/classifier/eval.py", line 28, in evaluate
    log.info(f"Instantiating datamodule <{cfg.datamodule._target_}>")
                                          ^^^^^^^^^^^^^^
  File "/workspace/.pyenv_mirror/user/current/lib/python3.11/site-packages/omegaconf/dictconfig.py", line 359, in __getattr__
    self._format_and_raise(key=key, value=None, cause=e)
  File "/workspace/.pyenv_mirror/user/current/lib/python3.11/site-packages/omegaconf/base.py", line 231, in _format_and_raise
    format_and_raise(
  File "/workspace/.pyenv_mirror/user/current/lib/python3.11/site-packages/omegaconf/_utils.py", line 819, in format_and_raise
    _raise(ex, cause)
  File "/workspace/.pyenv_mirror/user/current/lib/python3.11/site-packages/omegaconf/_utils.py", line 797, in _raise
    raise ex.with_traceback(sys.exc_info()[2])  # set env var OC_CAUSE=1 for full trace
    ^^^^^^^^^^^^^^^^^^^^^^^^^^^^^^^^^^^^^^^^^^
  File "/workspace/.pyenv_mirror/user/current/lib/python3.11/site-packages/omegaconf/dictconfig.py", line 351, in __getattr__
    return self._get_impl(
           ^^^^^^^^^^^^^^^
  File "/workspace/.pyenv_mirror/user/current/lib/python3.11/site-packages/omegaconf/dictconfig.py", line 442, in _get_impl
    node = self._get_child(
           ^^^^^^^^^^^^^^^^
  File "/workspace/.pyenv_mirror/user/current/lib/python3.11/site-packages/omegaconf/basecontainer.py", line 73, in _get_child
    child = self._get_node(
            ^^^^^^^^^^^^^^^
  File "/workspace/.pyenv_mirror/user/current/lib/python3.11/site-packages/omegaconf/dictconfig.py", line 475, in _get_node
    self._validate_get(key)
  File "/workspace/.pyenv_mirror/user/current/lib/python3.11/site-packages/omegaconf/dictconfig.py", line 164, in _validate_get
    self._format_and_raise(
  File "/workspace/.pyenv_mirror/user/current/lib/python3.11/site-packages/omegaconf/base.py", line 231, in _format_and_raise
    format_and_raise(
  File "/workspace/.pyenv_mirror/user/current/lib/python3.11/site-packages/omegaconf/_utils.py", line 899, in format_and_raise
    _raise(ex, cause)
  File "/workspace/.pyenv_mirror/user/current/lib/python3.11/site-packages/omegaconf/_utils.py", line 797, in _raise
    raise ex.with_traceback(sys.exc_info()[2])  # set env var OC_CAUSE=1 for full trace
    ^^^^^^^^^^^^^^^^^^^^^^^^^^^^^^^^^^^^^^^^^^
omegaconf.errors.ConfigAttributeError: Key 'datamodule' is not in struct
    full_key: datamodule
    object_type=dict
[2023-07-03 06:19:56,505][classifier.utils.utils][INFO] - Output dir: /workspace/TSOA-Emlops-Deep-Learning-package/outputs/2023-07-03/06-19-56
